<robot name="tuna">

	<link name="base_link">
		<visual>
			<geometry>
				<mesh filename="package://tuna_gazebo/meshes/boat.dae"/>
			</geometry>
		</visual>
	</link>

	<link name="prop_left">
		<visual>
			<geometry>
				<mesh filename="package://tuna_gazebo/meshes/prop_left.dae"/>
			</geometry>
		</visual>
	</link>

	<link name="prop_right">
		<visual>
			<geometry>
				<mesh filename="package://tuna_gazebo/meshes/prop_right.dae"/>
			</geometry>
		</visual>
	</link>

	<link name="gps"/>
	<link name="imu_link"/>

	<joint name="base_to_imu" type="fixed">
		<parent link="base_link"/>
		<child link="imu_link"/>
		<origin xyz="0.193 0 0.004" rpy="0 0 0" />
	</joint>

	<joint name="base_to_gps" type="fixed"> 
		<parent link="base_link"/>
		<child link="gps"/>
		<origin xyz="0.016 0 0.12" rpy="0 0 0" />
	</joint>

	<joint name="base_to_prop_right" type="continuous">
		<parent link="base_link"/>
		<child link="prop_right"/>
		<origin xyz="-0.14 -0.018 -0.043" rpy="0 -0.19 0" />
		<limit effort="1" velocity="12"/>
		<axis xyz="1 0 0"/>
	</joint>

	<joint name="base_to_prop_left" type="continuous">
		<parent link="base_link"/>
		<child link="prop_left"/>
		<origin xyz="-0.14 0.018 -0.043" rpy="0 -0.19 0" />
		<limit effort="1" velocity="12"/>
		<axis xyz="1 0 0"/>
	</joint>

</robot>
